Workbook

Sheet tmpA1A6
A1: KANE-JONES
A2: SALES REGISTER
A3: 7/1/2026 TO 7/15/2026
A4: VOUCHER DATE | B4: PARTICULARS | C4: VCHNO | D4: Purchase Order No | E4: TRANSACTION VALUE | F4: RECEIVED AMOUNT | G4: OUTSTANDING AMOUNT | H4: GROSS REVENUE | I4: COST | J4: GROSS PROFIT | K4: % PROFIT | L4: NARRATION
A5: 46204 | B5: Walk in Customer | C5: ann-INV142 | E5: 18500 | F5: 18500 | G5: 0 | H5: 18500 | I5: 16759 | J5: 1741 | K5: 9
B6: ITEM/SERVICE | C6: QUANTITY | D6: RATE | E6: COST | F6: DESCRIPTION
B7: Trophy | C7: 1 | D7: 9000 | E7: 8122
B8: Goldberg 60cl | C8: 1 | D8: 9500 | E8: 8637
A10: 46204 | B10: Walk in Customer | C10: ann-INV143 | E10: 5400 | F10: 5400 | G10: 0 | H10: 5400 | I10: 5200 | J10: 200 | K10: 4
B11: ITEM/SERVICE | C11: QUANTITY | D11: RATE | E11: COST | F11: DESCRIPTION
B12: Maltina Pet 33cl | C12: 1 | D12: 5400 | E12: 5200
A14: 46204 | B14: Eniola Marketer | C14: ann-INV144 | E14: 1533700 | F14: 1533700 | G14: 0 | H14: 1533700 | I14: 1579003 | J14: -45303 | K14: -3
B15: ITEM/SERVICE | C15: QUANTITY | D15: RATE | E15: COST | F15: DESCRIPTION
B16: Maltina Pet 33cl | C16: 200 | D16: 4950 | E16: 1040000
B17: Maltina Pet 50cl | C17: 35 | D17: 8020 | E17: 268975
B18: Maltina Can | C18: 20 | D18: 13150 | E18: 270028 | J18: =SUM(J5:J14) -> -43362
A20: 46205 | B20: Ameh Mathew | C20: ann-INV145 | E20: 821130 | F20: 821130 | G20: 0 | H20: 821130 | I20: 811313 | J20: 9817 | K20: 1
B21: ITEM/SERVICE | C21: QUANTITY | D21: RATE | E21: COST | F21: DESCRIPTION
B22: Maltina Pet 33cl | C22: 40 | D22: 4900 | E22: 208000
B23: Heineken Sleek Can | C23: 15 | D23: 17845 | E23: 256500
B24: Goldberg Can 50cl | C24: 3 | D24: 16145 | E24: 45746
B25: 33 Export Can | C25: 2 | D25: 16145 | E25: 31110
B26: Maltina Can | C26: 5 | D26: 13200 | E26: 67507
B27: Desperados Can | C27: 2 | D27: 22740 | E27: 43190
B28: Legend Can 44cl | C28: 2 | D28: 21170 | E28: 40810
B29: Tiger Bottle | C29: 6 | D29: 15525 | E29: 89400
B30: Turbo King Bottle 60cl | C30: 2 | D30: 8880 | E30: 17050
B31: NB Empties | C31: 8 | D31: 1500 | E31: 12000
A33: 46205 | B33: Ameh Mathew | C33: ann-INV146 | E33: 256500 | F33: 256500 | G33: 0 | H33: 256500 | I33: 256500 | J33: 0 | K33: 0
B34: ITEM/SERVICE | C34: QUANTITY | D34: RATE | E34: COST | F34: DESCRIPTION
B35: Heineken Sleek Can | C35: 15 | D35: 17100 | E35: 256500
A37: 46205 | B37: TD Odiolowo | C37: ann-INV147 | E37: 86000 | F37: 86000 | G37: 0 | H37: 86000 | I37: 86374 | J37: -374 | K37: 0
B38: ITEM/SERVICE | C38: QUANTITY | D38: RATE | E38: COST | F38: DESCRIPTION
B39: Goldberg 60cl | C39: 10 | D39: 8600 | E39: 86374
A41: 46205 | B41: Ameh Mathew | C41: ann-INV148 | E41: 62070 | F41: 62070 | G41: 0 | H41: 62070 | I41: 59758 | J41: 2312 | K41: 4
B42: ITEM/SERVICE | C42: QUANTITY | D42: RATE | E42: COST | F42: DESCRIPTION
B43: Medium Stout | C43: 1 | D43: 17700 | E43: 17150
B44: Trophy | C44: 1 | D44: 8500 | E44: 8122
B45: 33 Export 60cl | C45: 1 | D45: 9200 | E45: 8990
B46: Heineken Bottle 60cl | C46: 2 | D46: 13335 | E46: 25496
...

Sheet tmp32C7
A1: KANE-JONES
A2: SALES REGISTER
A3: 7/16/2026 TO 7/31/2026
A4: VOUCHER DATE | B4: PARTICULARS | C4: VCHNO | D4: Purchase Order No | E4: QUANTITY | F4: TRANSACTION VALUE | G4: RECEIVED AMOUNT | H4: OUTSTANDING AMOUNT | I4: GROSS REVENUE | J4: COST | K4: GROSS PROFIT | L4: % PROFIT | M4: NARRATION
A5: 46219 | B5: Taiwo SR | C5: ann-INV283 | E5: 10 | F5: 178125 | G5: 178125 | H5: 0 | I5: 178125 | J5: 168575 | K5: 9550 | L5: 5
B6: ITEM/SERVICE | C6: QUANTITY | D6: RATE | E6: COST | F6: DESCRIPTION
B7: Desperados Can | C7: 5 cans | D7: 22740 | E7: 107975
B8: CLIMAX CAN | C8: 5 cans | D8: 12885 | E8: 60600
A10: 46219 | B10: Walk in Customer | C10: ann-INV284 | E10: 1 | F10: 5300 | G10: 5300 | H10: 0 | I10: 5300 | J10: 5200 | K10: 100 | L10: 2
B11: ITEM/SERVICE | C11: QUANTITY | D11: RATE | E11: COST | F11: DESCRIPTION
B12: Maltina Pet 33cl | C12: 1 pets | D12: 5300 | E12: 5200
A14: 46219 | B14: Rita SR | C14: ann-INV285 | E14: 190 | F14: 1877025 | G14: 1000000 | H14: 877025 | I14: 1877025 | J14: 1892820 | K14: -15795 | L14: -1
B15: ITEM/SERVICE | C15: QUANTITY | D15: RATE | E15: COST | F15: DESCRIPTION
B16: Maltina Pet 33cl | C16: 100 pets | D16: 5000 | E16: 520000
B17: Goldberg Can 50cl | C17: 30 cans | D17: 15655 | E17: 457417
B18: Heineken Sleek Can | C18: 15 cans | D18: 17200 | E18: 256500
B19: 33 Export Can | C19: 25 cans | D19: 15655 | E19: 388875
B20: Maltina Can | C20: 20 cans | D20: 12900 | E20: 270028
A22: 46219 | B22: Walk in Customer | C22: ann-INV286 | E22: 3 | F22: 24060 | G22: 24060 | H22: 0 | I22: 24060 | J22: 23255 | K22: 805 | L22: 3
B23: ITEM/SERVICE | C23: QUANTITY | D23: RATE | E23: COST | F23: DESCRIPTION
B24: Maltina Pet 33cl | C24: 2 pets | D24: 5300 | E24: 10400
B25: Fayrouz Can | C25: 1 cans | D25: 13460 | E25: 12855
A27: 46219 | B27: Walk in Customer | C27: ann-INV287 | E27: 1 | F27: 5300 | G27: 0 | H27: 5300 | I27: 5300 | J27: 5200 | K27: 100 | L27: 2
B28: ITEM/SERVICE | C28: QUANTITY | D28: RATE | E28: COST | F28: DESCRIPTION
B29: Maltina Pet 33cl | C29: 1 pets | D29: 5300 | E29: 5200
A31: 46219 | B31: Eniola Marketer | C31: ann-INV288 | E31: 110 | F31: 575000 | G31: 575000 | H31: 0 | I31: 575000 | J31: 549837 | K31: 25163 | L31: 4
B32: ITEM/SERVICE | C32: QUANTITY | D32: RATE | E32: COST | F32: DESCRIPTION
B33: Goldberg 60cl | C33: 25 crt | D33: 9200 | E33: 216419
B34: Trophy | C34: 25 crt | D34: 8200 | E34: 203047
B35: 33 Export 60cl | C35: 5 crt | D35: 9200 | E35: 44950
B36: NB Empties | C36: 30 Empty | D36: 1800 | E36: 45421
B37: IB Empties | C37: 25 Empty | D37: 1600 | E37: 40000
A39: 46219 | B39: MRS IK. | C39: ann-INV289 | E39: 3 | F39: 27400 | G39: 27400 | H39: 0 | I39: 27400 | J39: 25435 | K39: 1965 | L39: 7
B40: ITEM/SERVICE | C40: QUANTITY | D40: RATE | E40: COST | F40: DESCRIPTION
B41: Goldberg 60cl | C41: 2 crt | D41: 9200 | E41: 17313
B42: Trophy | C42: 1 crt | D42: 9000 | E42: 8122
A44: 46219 | B44: Walk in Customer | C44: ann-INV290 | E44: 2 | F44: 24950 | G44: 0 | H44: 24950 | I44: 24950 | J44: 23877 | K44: 1073 | L44: 4
B45: ITEM/SERVICE | C45: QUANTITY | D45: RATE | E45: COST | F45: DESCRIPTION
B46: Heineken Bottle 60cl | C46: 1 crt | D46: 13350 | E46: 12747
B47: Star Bottle 60cl | C47: 1 crt | D47: 11600 | E47: 11130
...

Sheet tmp3F5D
A1: KANE-JONES
A2: Inventory Summary
A3: 7/1/2026 To 7/31/2026
A4: ITEM | B4: NO. OF UNITS | C4: UOM | D4: RATE PER UNIT | E4: VALUE | F4: DEFAULT PURCHASE PRICE
A5: Guiness | B5: 2419 | E5: 30129450
A6: Can | B6: 2144 | E6: 25728000
A7: Malta Gns Can. | B7: 2144 | C7: cans | D7: 12000 | E7: 25728000 | F7: 0
A8: RGB | B8: 275 | E8: 4401450
A9: Big Stout | B9: 140 | C9: crt | D9: 15330 | E9: 2146200 | F9: 15330
A10: Medium Stout | B10: 60 | C10: crt | D10: 17150 | E10: 1029000 | F10: 17150
A11: ORIJIN BT | B11: 0 | C11: crt | D11: 0 | E11: 0 | F11: 0
A12: Small Guinness Stout | B12: 0 | C12: crt | D12: 0 | E12: 0 | F12: 0
A13: Smirnoff Ice. | B13: 75 | C13: crt | D13: 16350 | E13: 1226250 | F13: 0
A14: IntlB | B14: 192 | E14: 1784215
A15: Can | B15: 0 | E15: 0
A16: TROPHY CAN | B16: 0 | C16: cans | D16: 0 | E16: 0 | F16: 0
A17: RGB | B17: 192 | E17: 1784215
A18: Budweiser | B18: 68 | C18: crt | D18: 10410 | E18: 707880 | F18: 0
A19: Castle Lite | B19: 60 | C19: crt | D19: 9280 | E19: 556800 | F19: 0
A20: Trophy | B20: 64 | C20: crt | D20: 8118 | E20: 519535 | F20: 8200
A21: NB PLC | B21: 28790 | E21: 260434163
A22: Can | B22: 2071 | E22: 35138079
A23: 33 Export Can | B23: 345 | C23: cans | D23: 15555 | E23: 5366475 | F23: 15555
A24: Amstel Can | B24: 2 | C24: cans | D24: 13911 | E24: 27821 | F24: 140750
A25: CLIMAX CAN | B25: 14 | C25: cans | D25: 12120 | E25: 169680 | F25: 0
A26: Desperados Can | B26: 92 | C26: cans | D26: 21595 | E26: 1986740 | F26: 21595
A27: Fayrouz Can | B27: 176 | C27: cans | D27: 12855 | E27: 2262480 | F27: 12855
A28: Goldberg Can 50cl | B28: 5 | C28: cans | D28: 15247 | E28: 76236 | F28: 15555
A29: Heineken Can 50cl | B29: 65 | C29: cans | D29: 22775 | E29: 1480375 | F29: 22775
A30: Heineken Sleek Can | B30: 1277 | C30: cans | D30: 17100 | E30: 21836700 | F30: 17100
A31: Legend Can 44cl | B31: 94 | C31: cans | D31: 20405 | E31: 1918070 | F31: 20405
A32: Maltina Can | B32: 1 | C32: cans | D32: 13501 | E32: 13501 | F32: 14070
A33: Pet | B33: 12269 | E33: 64180370
A34: ACE BITTERS | B34: 23 | C34: pets | D34: 19305 | E34: 444015 | F34: 0
A35: Fayrouz Pet | B35: 0 | C35: pets | D35: 0 | E35: 0 | F35: 4720
A36: Maltina Pet 25cl | B36: 0 | C36: pets | D36: 0 | E36: 0 | F36: 4000
A37: Maltina Pet 33cl | B37: 12223 | C37: pets | D37: 5200 | E37: 63559600 | F37: 5200
A38: Maltina Pet 50cl | B38: 23 | C38: pets | D38: 7685 | E38: 176755 | F38: 7685
A39: RGB | B39: 12430 | E39: 119702397
A40: 33 Export 60cl | B40: 2705 | C40: crt | D40: 8990 | E40: 24317950 | F40: 8990
...

Sheet tmpCEF3
A1: KANE-JONES
A2: DAY BOOK
A3: 7/1/2026 TO 7/31/2026
A4: VOUCHER DATE | B4: DEBIT | C4: CREDIT | D4: VCH TYPE | E4: VCHNO | F4: DEBIT AMOUNT | G4: CREDIT AMOUNT
A5: 46205 | B5: Sales Return | C5: Ameh Mathew | D5: Credit Note | E5: ann-SLR17 | G5: 267675
B6: ITEM/SERVICE | C6: QUANTITY | D6: RATE | E6: DESCRIPTION
B7: Heineken Sleek Can | C7: 15 cans | D7: 17845
A9: 46205 | B9: Sales Return | C9: Ameh Mathew | D9: Credit Note | E9: ann-SLR20 | G9: 11100
B10: ITEM/SERVICE | C10: QUANTITY | D10: RATE | E10: DESCRIPTION
B11: NB Empties | C11: 3 Empty | D11: 1500
B12: IB Empties | C12: 1 Empty | D12: 1600
B13: GNS EMPTIES | C13: 1 Empty | D13: 5000
A15: 46205 | B15: Sales Return | C15: TD Odiolowo | D15: Credit Note | E15: ann-SLR18 | G15: 15000
B16: ITEM/SERVICE | C16: QUANTITY | D16: RATE | E16: DESCRIPTION
B17: NB Empties | C17: 10 Empty | D17: 1500
A19: 46205 | B19: Sales Return | C19: Ameh Mathew | D19: Credit Note | E19: ann-SLR19 | G19: 12000
B20: ITEM/SERVICE | C20: QUANTITY | D20: RATE | E20: DESCRIPTION
B21: NB Empties | C21: 8 Empty | D21: 1500
A23: 46206 | B23: Sales Return | C23: DESOLA STORE | D23: Credit Note | E23: ann-SLR21 | G23: 835000
B24: ITEM/SERVICE | C24: QUANTITY | D24: RATE | E24: DESCRIPTION
B25: Maltina Pet 33cl | C25: 148 pets | D25: 5100
B26: Maltina Pet 50cl | C26: 10 pets | D26: 8020
A28: 46206 | B28: Sales Return | C28: Ameh Mathew | D28: Credit Note | E28: ann-SLR23 | G28: 57000
B29: ITEM/SERVICE | C29: QUANTITY | D29: RATE | E29: DESCRIPTION
B30: NB Empties | C30: 38 Empty | D30: 1500
A32: 46206 | B32: Sales Return | C32: Abbey Illisan | D32: Credit Note | E32: ann-SLR22 | G32: 630000
B33: ITEM/SERVICE | C33: QUANTITY | D33: RATE | E33: DESCRIPTION
B34: NB Empties | C34: 420 Empty | D34: 1500
A36: 46206 | B36: Sales Return | C36: TD Odiolowo | D36: Credit Note | E36: ann-SLR24 | G36: 45000
B37: ITEM/SERVICE | C37: QUANTITY | D37: RATE | E37: DESCRIPTION
B38: NB Empties | C38: 30 Empty | D38: 1500
A40: 46207 | B40: Sales Return | C40: XXIII LOUNGE | D40: Credit Note | E40: ann-SLR25 | G40: 43500
B41: ITEM/SERVICE | C41: QUANTITY | D41: RATE | E41: DESCRIPTION
B42: NB Empties | C42: 29 Empty | D42: 1500
A44: 46207 | B44: Sales Return | C44: Abbey Illisan | D44: Credit Note | E44: ann-SLR26 | G44: 441000
B45: ITEM/SERVICE | C45: QUANTITY | D45: RATE | E45: DESCRIPTION
B46: NB Empties | C46: 294 Empty | D46: 1500
A48: 46209 | B48: Sales Return | C48: Eniola Marketer | D48: Credit Note | E48: ann-SLR27 | G48: 72000
B49: ITEM/SERVICE | C49: QUANTITY | D49: RATE | E49: DESCRIPTION
B50: IB Empties | C50: 45 Empty | D50: 1600
...

Sheet July 1st Sales Report
A1: Date | B1: Product | C1: Cases_Sold | D1: Unit_Price_NGN | E1: Amount_NGN | F1: Customer | G1: Invoice No | I1: Product | J1: Quantity | K1: Revenue | L1: % of Total Revenue | N1: Total Revnue | O1: Total Cases Sold | P1: Total transaction
A2: 46204 | B2: Trophy | C2: 1 | D2: 9000 | E2: =C2*D2 -> 9000 | F2: Walk in Customer 1 | G2: ann-INV142 | I2: Trophy | J2: 1 | K2: 9000 | L2: =K2/K$7 -> 0.0057781202 | N2: =K7 -> 1557600 | O2: =J7 -> 258 | P2: =COUNT(I2:I6,J2:J6) -> 5
A3: 46204 | B3: Goldberg 60cl | C3: 1 | D3: 9500 | E3: =C3*D3 -> 9500 | F3: Walk in Customer 1 | G3: ann-INV142 | I3: Goldberg 60cl | J3: 1 | K3: 9500 | L3: =K3/K$7 -> 0.0060991269
A4: 46204 | B4: Maltina Pet 33cl | C4: 1 | D4: 5400 | E4: =C4*D4 -> 5400 | F4: Walk in Customer 2 | G4: ann-INV143 | I4: Maltina Pet 33cl | J4: 201 | K4: =SUM(E4+E5) -> 995400 | L4: =K4/K$7 -> 0.63906009
A5: 46204 | B5: Maltina Pet 33cl | C5: 200 | D5: 4950 | E5: =C5*D5 -> 990000 | F5: Eniola Marketer | G5: ann-INV144 | I5: Maltina Pet 50cl | J5: 35 | K5: =E6 -> 280700 | L5: =K5/K$7 -> 0.18021315
A6: 46204 | B6: Maltina Pet 50cl | C6: 35 | D6: 8020 | E6: =C6*D6 -> 280700 | F6: Eniola Marketer | G6: ann-INV144 | I6: Maltina Can | J6: 20 | K6: =E7 -> 263000 | L6: =K6/K$7 -> 0.16884951
A7: 46204 | B7: Maltina Can | C7: 20 | D7: 13150 | E7: =C7*D7 -> 263000 | F7: Eniola Marketer | G7: ann-INV144 | I7: Grand Total | J7: =C8 -> 258 | K7: =SUM(K2:K6) -> 1557600 | L7: =SUM(L2:L6) -> 1
B8: Grand Total | C8: =SUM(C2:C7) -> 258 | D8: =SUM(D2:D7) -> 50020 | E8: =SUM(E2:E7) -> 1557600
I20: Customer | J20: Amount_NGN | K20: % of Total Revenue | L20: Gross Profit
I21: Walk in Customer 1 | J21: =E2+E3 -> 18500 | K21: =J21/E$8 -> 0.011877247 | L21: 0.09
I22: Walk in Customer 2 | J22: =E4 -> 5400 | K22: =J22/E$8 -> 0.0034668721 | L22: 0.04
I23: Eniola Marketer | J23: =SUM(E5:E7) -> 1533700 | K23: =J23/E8 -> 0.98465588 | L23: -0.03
I24: Total | J24: =SUM(J21:J23) -> 1557600 | K24: 1
I28: Invoice No | J28: Amount_NGN | K28: Gross Profit
I29: ann-INV142 | J29: 18500 | K29: 0.09
I30: ann-INV143 | J30: 5400 | K30: 0.04
I31: ann-INV144 | J31: 1533700 | K31: -0.03
I32: Total | J32: =SUM(J29:J31) -> 1557600

Sheet July 2nd Sales Report
A1: Date | B1: Product | C1: Cases_Sold | D1: Unit_Price_NGN | E1: Amount_NGN | F1: Customer | G1: Invoice No | I1: Product | J1: Quantity | K1: Revenue | L1: % of Total Revenue | N1: Total Revnue | O1: Total Cases Sold | P1: Total transaction
A2: 46205 | B2: Maltina Pet 33cl | C2: 40 | D2: 4900 | E2: =C2*D2 -> 196000 | F2: Ameh Mathew | G2: ann-INV145 | I2: Maltina Pet 33cl | J2: =C2+C25 -> 300 | K2: =SUM(E2+E25) -> 1496000 | L2: =K2/K$20 -> 0.35371991 | N2: =K20 -> 4229335 | O2: =J20 -> 488 | P2: =COUNT(I2:I19,J2:J19) -> 18
A3: 46205 | B3: Heineken Sleek Can | C3: 15 | D3: 17845 | E3: =C3*D3 -> 267675 | F3: Ameh Mathew | G3: ann-INV145 | I3: Heineken Sleek Can | J3: =C3+C11+C21 -> 32 | K3: =E3+E11+E21 -> 558375 | L3: =K3/K$20 -> 0.1320243
A4: 46205 | B4: Goldberg Can 50cl | C4: 3 | D4: 16145 | E4: =C4*D4 -> 48435 | F4: Ameh Mathew | G4: ann-INV145 | I4: Goldberg Can 50cl | J4: =C4+C18 -> 33 | K4: =SUM(E4+E18) -> 518085 | L4: =K4/K$20 -> 0.12249798
A5: 46205 | B5: 33 Export Can | C5: 2 | D5: 16145 | E5: =C5*D5 -> 32290 | F5: Ameh Mathew | G5: ann-INV145 | I5: 4th Street wine | J5: 1 | K5: =E26 -> 24235 | L5: =K5/K$20 -> 0.0057302153
A6: 46205 | B6: Maltina Can | C6: 5 | D6: 13200 | E6: =C6*D6 -> 66000 | F6: Ameh Mathew | G6: ann-INV145 | I6: Maltina Can | J6: =C6+C19 -> 40 | K6: =SUM(E6+E19) -> 517500 | L6: =K6/K$20 -> 0.12235966
A7: 46205 | B7: Desperados Can | C7: 2 | D7: 22740 | E7: =C7*D7 -> 45480 | F7: Ameh Mathew | G7: ann-INV145 | I7: Desperados Can | J7: =C7+C20+C22 -> 8 | K7: =SUM(E7+E20+E22) -> 176695 | L7: =K7/K$20 -> 0.041778436
A8: 46205 | B8: Legend Can 44cl | C8: 2 | D8: 21170 | E8: =C8*D8 -> 42340 | F8: Ameh Mathew | G8: ann-INV145 | I8: Legend Can 44cl | J8: 2 | K8: =E8 -> 42340 | L8: =K8/K$20 -> 0.01001103
A9: 46205 | B9: Tiger Bottle | C9: 6 | D9: 15525 | E9: =C9*D9 -> 93150 | F9: Ameh Mathew | G9: ann-INV145 | I9: Tiger Bottle | J9: 6 | K9: =E9 -> 93150 | L9: =K9/K$20 -> 0.022024739
A10: 46205 | B10: Turbo King Bottle 60cl | C10: 2 | D10: 8880 | E10: =C10*D10 -> 17760 | F10: Ameh Mathew | G10: ann-INV145 | I10: Turbo King Bottle 60cl | J10: 2 | K10: =E10 -> 17760 | L10: =K10/K$20 -> 0.0041992417
A11: 46205 | B11: Heineken Sleek Can | C11: 15 | D11: 17100 | E11: =C11*D11 -> 256500 | F11: Ameh Mathew | G11: ann-INV146 | I11: Goldberg 60cl | J11: =C12+C23 -> 12 | K11: =E12+E23 -> 103200 | L11: =K11/K$20 -> 0.024400999
A12: 46205 | B12: Goldberg 60cl | C12: 10 | D12: 8600 | E12: =C12*D12 -> 86000 | F12: TD Odiolowo | G12: ann-INV147 | I12: Medium Stout | J12: 1 | K12: =E13 -> 17700 | L12: =K12/K$20 -> 0.0041850551
A13: 46205 | B13: Medium Stout | C13: 1 | D13: 17700 | E13: =C13*D13 -> 17700 | F13: Ameh Mathew | G13: ann-INV148 | I13: Trophy | J13: 1 | K13: =E14 -> 8500 | L13: =K13/K$20 -> 0.0020097722
A14: 46205 | B14: Trophy | C14: 1 | D14: 8500 | E14: =C14*D14 -> 8500 | F14: Ameh Mathew | G14: ann-INV148 | I14: 33 Export 60cl | J14: 1 | K14: =E15 -> 9200 | L14: =K14/K$20 -> 0.0021752829
A15: 46205 | B15: 33 Export 60cl | C15: 1 | D15: 9200 | E15: =C15*D15 -> 9200 | F15: Ameh Mathew | G15: ann-INV148 | I15: Heineken Bottle 60cl | J15: 2 | K15: =E16 -> 26670 | L15: =K15/K$20 -> 0.0063059559
A16: 46205 | B16: Heineken Bottle 60cl | C16: 2 | D16: 13335 | E16: =C16*D16 -> 26670 | F16: Ameh Mathew | G16: ann-INV148 | I16: 33 Export Can | J16: =C5+C17 -> 27 | K16: =E5+E17 -> 423665 | L16: =K16/K$20 -> 0.10017296
A17: 46205 | B17: 33 Export Can | C17: 25 | D17: 15655 | E17: =C17*D17 -> 391375 | F17: Rita SR | G17: ann-INV152 | I17: Maltina Pet 50cl | J17: =C27+C28 -> 15 | K17: =E27+E28 -> 120300 | L17: =K17/K$20 -> 0.028444188
A18: 46205 | B18: Goldberg Can 50cl | C18: 30 | D18: 15655 | E18: =C18*D18 -> 469650 | F18: Rita SR | G18: ann-INV152 | I18: CLIMAX CAN | J18: 2 | K18: =E29 -> 25770 | L18: =K18/K$20 -> 0.0060931565
A19: 46205 | B19: Maltina Can | C19: 35 | D19: 12900 | E19: =C19*D19 -> 451500 | F19: Rita SR | G19: ann-INV152 | I19: ACE BITTERS | J19: 2 | K19: =E30 -> 41310 | L19: =K19/K$20 -> 0.009767493
A20: 46205 | B20: Desperados Can | C20: 5 | D20: 21695 | E20: =C20*D20 -> 108475 | F20: Rita SR | G20: ann-INV152 | I20: Grand Total | J20: =C31 -> 488 | K20: =E31 -> 4229335 | L20: =K20/K$20 -> 1
A21: 46205 | B21: Heineken Sleek Can | C21: 2 | D21: 17100 | E21: =C21*D21 -> 34200 | F21: Ameh Mathew | G21: ann-INV153
A22: 46205 | B22: Desperados Can | C22: 1 | D22: 22740 | E22: =C22*D22 -> 22740 | F22: Ameh Mathew | G22: ann-INV153
A23: 46205 | B23: Goldberg 60cl | C23: 2 | D23: 8600 | E23: =C23*D23 -> 17200 | F23: TD Odiolowo | G23: ann-INV154
A24: 46205 | B24: Turbo King Bottle 60cl | C24: 1 | D24: 8880 | E24: =C24*D24 -> 8880 | F24: Ameh Mathew | G24: ann-INV155
A25: 46205 | B25: Maltina Pet 33cl | C25: 260 | D25: 5000 | E25: =C25*D25 -> 1300000 | F25: Eniola Marketer | G25: ann-INV156
A26: 46205 | B26: 4th Street wine | C26: 1 | D26: 24235 | E26: =C26*D26 -> 24235 | F26: Eniola Marketer | G26: ann-INV156
A27: 46205 | B27: Maltina Pet 50cl | C27: 5 | D27: 8020 | E27: =C27*D27 -> 40100 | F27: Eniola Marketer | G27: ann-INV157
A28: 46205 | B28: Maltina Pet 50cl | C28: 10 | D28: 8020 | E28: =C28*D28 -> 80200 | F28: Eniola Marketer | G28: ann-INV158
A29: 46205 | B29: CLIMAX CAN | C29: 2 | D29: 12885 | E29: =C29*D29 -> 25770 | F29: Mr Lekan Ojifini | G29: ann-INV159
A30: 46205 | B30: ACE BITTERS | C30: 2 | D30: 20655 | E30: =C30*D30 -> 41310 | F30: Mr Lekan Ojifini | G30: ann-INV159
B31: Grand Total | C31: =SUM(C2:C30) -> 488 | D31: =SUM(D2:D30) -> 413025 | E31: =SUM(E2:E30) -> 4229335
E36: =SUM(E2:E11) -> 1065630
E37: =SUM(E13:E16) -> 62070
E38: =+E21+E22 -> 56940 | I38: Customer | J38: Amount_NGN | K38: % of Total Revenue | L38: Gross Profit
I39: Ameh Mathew | J39: =E36+E37+E38+E24 -> 1193520 | K39: =J39/E$31 -> 0.28220039 | L39: %
I40: TD Odiolowo | J40: =E12+E23 -> 103200 | K40: =J40/E$31 -> 0.024400999 | L40: 0.09
I41: Rita SR | J41: =SUM(E17:E20) -> 1421000 | K41: =J41/E$31 -> 0.33598663 | L41: 0
I42: Eniola Marketer | J42: =SUM(E25:E28) -> 1444535 | K42: =J42/E$31 -> 0.34155133
I43: Mr Lekan Ojifini | J43: =E29+E30 -> 67080 | K43: =J43/E$31 -> 0.015860649 | L43: 0.06
I44: Total | J44: =SUM(J39:J43) -> 4229335 | K44: =J44/E$31 -> 1
...

Sheet July 3rd Sales Report
A1: Date | B1: Product | C1: Cases_Sold | D1: Unit_Price_NGN | E1: Amount_NGN | F1: Customer | G1: Invoice No | I1: Product | J1: Quantity | K1: Revenue | L1: % of Total Revenue | N1: Total Revnue | O1: Total Cases Sold | P1: Total transaction
A2: 46204 | B2: Heineken Bottle 60cl | C2: 280 | D2: 12930 | E2: =C2*D2 -> 3620400 | F2: Abbey Illisan | G2: ann-INV161 | I2: Heineken Bottle 60cl | J2: =SUM(C2+C7+C26+C30) -> 432 | K2: =E2+E7+E26+E30 -> 5577850 | L2: =K2/K$18 -> 0.3611955 | N2: =E32 -> 15442745 | O2: =J18 -> 1474 | P2: =COUNT(I2:I17,J2:J17) -> 16
A3: 46206 | B3: Goldberg 60cl | C3: 210 | D3: 8990 | E3: =C3*D3 -> 1887900 | F3: Abbey Illisan | G3: ann-INV162 | I3: Goldberg 60cl | J3: =C3+C14+C23+C27 -> 252 | K3: =E3+E14+E23+E27 -> 2627755 | L3: =K3/K$18 -> 0.17016113
A4: 46206 | B4: 33 Export 60cl | C4: 140 | D4: 8990 | E4: =C4*D4 -> 1258600 | F4: Abbey Illisan | G4: ann-INV163 | I4: 33 Export 60cl | J4: =C4+C6+C21+C29 -> 296 | K4: =SUM(E4+E6+E21+E29) -> 2664400 | L4: =K4/K$18 -> 0.17253409
A5: 46206 | B5: Gulder Bottle | C5: 84 | D5: 11415 | E5: =C5*D5 -> 958860 | F5: Abbey Illisan | G5: ann-INV164 | I5: Gulder Bottle | J5: =C5+C13+C31 -> 173 | K5: =E5+E13+E31 -> 1968870 | L5: =K5/K$18 -> 0.12749482
A6: 46206 | B6: 33 Export 60cl | C6: 15 | D6: 9200 | E6: =C6*D6 -> 138000 | F6: Ameh Mathew | G6: ann-INV162 | I6: Amstel Bottle | J6: 1 | K6: =E8 -> 14450 | L6: =K6/K$18 -> 0.00093571447
A7: 46206 | B7: Heineken Bottle 60cl | C7: 10 | D7: 13335 | E7: =C7*D7 -> 133350 | F7: Ameh Mathew | G7: ann-INV162 | I7: Fayrouz Can | J7: =C9 -> 1 | K7: =E9 -> 13460 | L7: =K7/K$18 -> 0.0008716067
A8: 46206 | B8: Amstel Bottle | C8: 1 | D8: 14450 | E8: =C8*D8 -> 14450 | F8: Ameh Mathew | G8: ann-INV162 | I8: Turbo King Bottle 60cl | J8: =C10+C22 -> 6 | K8: =E10+E22 -> 53600 | L8: =K8/K$18 -> 0.0034708855
A9: 46206 | B9: Fayrouz Can | C9: 1 | D9: 13460 | E9: =C9*D9 -> 13460 | F9: Ameh Mathew | G9: ann-INV162 | I9: Tiger Bottle | J9: =C11 -> 1 | K9: =E11 -> 15525 | L9: =K9/K$18 -> 0.0010053264
A10: 46206 | B10: Turbo King Bottle 60cl | C10: 5 | D10: 8880 | E10: =C10*D10 -> 44400 | F10: Ameh Mathew | G10: ann-INV162 | I10: Legend 45cl | J10: =C12 -> 1 | K10: =E12 -> 15945 | L10: =K10/K$18 -> 0.0010325237
A11: 46206 | B11: Tiger Bottle | C11: 1 | D11: 15525 | E11: =C11*D11 -> 15525 | F11: Ameh Mathew | G11: ann-INV162 | I11: Heineken Sleek Can | J11: =C24+C28 -> 31 | K11: =E24+E28 -> 525300 | L11: =K11/K$18 -> 0.034015973
A12: 46206 | B12: Legend 45cl | C12: 1 | D12: 15945 | E12: =C12*D12 -> 15945 | F12: Ameh Mathew | G12: ann-INV162 | I12: Desperados Bottle | J12: =C25 -> 2 | K12: =E25 -> 45130 | L12: =K12/K$18 -> 0.0029224079
A13: 46206 | B13: Gulder Bottle | C13: 5 | D13: 11910 | E13: =C13*D13 -> 59550 | F13: Ameh Mathew | G13: ann-INV162 | I13: ACE BITTERS | J13: =C15 -> 30 | K13: =E15 -> 258000 | L13: =K13/K$18 -> 0.016706874
A14: 46206 | B14: ACE BITTERS | C14: 1 | D14: 20655 | E14: 20655 | F14: Ameh Mathew | G14: ann-INV164 | I14: Maltina Pet 33cl | J14: =C16+C19 -> 202 | K14: =E16+E19 -> 1010800 | L14: =K14/K$18 -> 0.065454684
A15: 46206 | B15: Goldberg 60cl | C15: 30 | D15: 8600 | E15: 258000 | F15: TD Odiolowo | G15: ann-INV163 | I15: Heineken Bottle 45cl | J15: =C17 -> 24 | K15: =E17 -> 428160 | L15: =K15/K$18 -> 0.027725641
A16: 46206 | B16: Maltina Pet 33cl | C16: 200 | D16: 5000 | E16: =C16*D16 -> 1000000 | F16: Eniola Marketer | G16: ann-INV167 | I16: Williams Bottle 60cl | J16: =C18 -> 20 | K16: =E18 -> 186900 | L16: =K16/K$18 -> 0.012102771
A17: 46206 | B17: Heineken Bottle 45cl | C17: 24 | D17: 17840 | E17: =C17*D17 -> 428160 | F17: ATW | G17: ann-INV165 | I17: Medium Stout | J17: =C20 -> 2 | K17: =E20 -> 36600 | L17: =K17/K$18 -> 0.002370045
A18: 46206 | B18: Williams Bottle 60cl | C18: 20 | D18: 9345 | E18: =C18*D18 -> 186900 | F18: Tmoney NB | G18: ann-INV166 | I18: Grand Total | J18: =C32 -> 1474 | K18: =SUM(K2:K17) -> 15442745 | L18: =K18/K$18 -> 1
A19: 46206 | B19: Maltina Pet 33cl | C19: 2 | D19: 5400 | E19: =C19*D19 -> 10800 | F19: tomaco | G19: ann-INV169
A20: 46206 | B20: Medium Stout | C20: 2 | D20: 18300 | E20: =C20*D20 -> 36600 | F20: tomaco | G20: ann-INV169
A21: 46206 | B21: 33 Export 60cl | C21: 1 | D21: 9200 | E21: =C21*D21 -> 9200 | F21: tomaco | G21: ann-INV169
A22: 46206 | B22: Turbo King Bottle 60cl | C22: 1 | D22: 9200 | E22: =C22*D22 -> 9200 | F22: tomaco | G22: ann-INV169
A23: 46206 | B23: Goldberg 60cl | C23: 1 | D23: 9200 | E23: =C23*D23 -> 9200 | F23: tomaco | G23: ann-INV169
A24: 46206 | B24: Goldberg 60cl | C24: 1 | D24: 9300 | E24: 9300 | F24: XXIII LOUNGE | G24: ann-INV168
A25: 46206 | B25: Desperados Bottle | C25: 2 | D25: 22565 | E25: =C25*D25 -> 45130 | F25: XXIII LOUNGE | G25: ann-INV168
A26: 46206 | B26: Heineken Bottle 60cl | C26: 2 | D26: 13950 | E26: =C26*D26 -> 27900 | F26: XXIII LOUNGE | G26: ann-INV168
A27: 46206 | B27: Heineken Sleek Can | C27: 40 | D27: 17750 | E27: 710000 | F27: Rita SR | G27: ann-INV171
A28: 46206 | B28: Heineken Sleek Can | C28: 30 | D28: 17200 | E28: =C28*D28 -> 516000 | F28: Rita SR | G28: ann-INV172
A29: 46206 | B29: Goldberg 60cl | C29: 140 | D29: 8990 | E29: =C29*D29 -> 1258600 | F29: WURAOLA | G29: ann-INV160
A30: 46206 | B30: Heineken Bottle 60cl | C30: 140 | D30: 12830 | E30: =C30*D30 -> 1796200 | F30: WURAOLA | G30: ann-INV160
A31: 46206 | B31: Gulder Bottle | C31: 84 | D31: 11315 | E31: =C31*D31 -> 950460 | F31: WURAOLA | G31: ann-INV160 | I31: Customer | J31: Amount_NGN | K31: % of Total Revenue | L31: Gross Profit
B32: Grand Total | C32: =SUM(C2:C31) -> 1474 | D32: =SUM(D2:D31) -> 371670 | E32: =SUM(E2:E31) -> 15442745 | I32: Abbey Illisan | J32: =SUM(E2:E5) -> 7725760 | K32: =J32/E$32 -> 0.50028411
I33: Ameh Mathew | J33: =SUM(E6:E14) -> 455335 | K33: =J33/E$32 -> 0.029485367
I34: TD Odiolowo | J34: =E15 -> 258000 | K34: =J34/E$32 -> 0.016706874
I35: Eniola Marketer | J35: =E16 -> 1000000 | K35: =J35/E$32 -> 0.064755327
I36: ATW | J36: =E17 -> 428160 | K36: =J36/E$32 -> 0.027725641
I37: Tmoney NB | J37: =E18 -> 186900 | K37: =J37/E$32 -> 0.012102771
I38: tomaco | J38: =SUM(E19:E23) -> 75000 | K38: =J38/E$32 -> 0.0048566495
I39: Rita SR | J39: =E27+E28 -> 1226000 | K39: =J39/E$32 -> 0.079390031
I40: XXIII LOUNGE | J40: =SUM(E24:E26) -> 82330 | K40: =J40/E$32 -> 0.0053313061
...

Sheet July 4th Sales Report 
A1: Date | B1: Product | C1: Cases_Sold | D1: Unit_Price_NGN | E1: Amount_NGN | F1: Customer | G1: Invoice No | I1: Product | J1: Quantity | K1: Revenue | L1: % of Total Revenue | N1: Total Revnue | O1: Total Cases Sold | P1: Total transaction
A2: 46207 | B2: Trophy | C2: 3 | D2: 9000 | E2: =C2*D2 -> 27000 | F2: Walk in Customer | G2: ann-INV173 | I2: Trophy | J2: =C2+C10 -> 53 | K2: =E2+E10 -> 442000 | L2: =K2/K$13 -> 0.060803905 | N2: =K13 -> 7269270 | O2: =J13 -> 756 | P2: =COUNT(I2:I4,J2:J6) -> 5
A3: 46207 | B3: Maltina Pet 33cl | C3: 30 | D3: 5000 | E3: =C3*D3 -> 150000 | F3: Walk in Customer | G3: ann-INV174 | I3: Maltina Pet 33cl | J3: =C3+C4+C16 -> 283 | K3: =E3+E4+E16 -> 1416500 | L3: =K3/K$13 -> 0.19486138
A4: 46207 | B4: Maltina Pet 33cl | C4: 248 | D4: 5000 | E4: =C4*D4 -> 1240000 | F4: Rita SR | G4: ann-INV175 | I4: Star Bottle 60cl | J4: =C6 -> 5 | K4: =E6 -> 56150 | L4: =K4/K$13 -> 0.0077242969
A5: 46207 | B5: Heineken Sleek Can | C5: 5 | D5: 17200 | E5: =C5*D5 -> 86000 | F5: Rita SR | G5: ann-INV175 | I5: 33 Export Can | J5: =C8 -> 20 | K5: =E8 -> 313100 | L5: =K5/K$13 -> 0.043071725
A6: 46207 | B6: Star Bottle 60cl | C6: 5 | D6: 11230 | E6: =C6*D6 -> 56150 | F6: Rita SR | G6: ann-INV176 | I6: Maltina Can | J6: =C9 -> 30 | K6: =E9 -> 387000 | L6: =K6/K$13 -> 0.053237808
A7: 46207 | B7: Heineken Sleek Can | C7: 5 | D7: 17200 | E7: =C7*D7 -> 86000 | F7: Rita SR | G7: ann-INV176 | I7: Fayrouz Can | J7: =C11 -> 3 | K7: =E11 -> 40380 | L7: =K7/K$13 -> 0.0055548907
A8: 46207 | B8: 33 Export Can | C8: 20 | D8: 15655 | E8: =C8*D8 -> 313100 | F8: Rita SR | G8: ann-INV176 | I8: Heineken Bottle 60cl | J8: =C12 -> 300 | K8: =E12 -> 3849000 | L8: =K8/K$13 -> 0.52948921
A9: 46207 | B9: Maltina Can | C9: 30 | D9: 12900 | E9: =C9*D9 -> 387000 | F9: Rita SR | G9: ann-INV176 | I9: Legend Bottle 60cl | J9: =C13 -> 40 | K9: =E13 -> 436600 | L9: =K9/K$13 -> 0.060061052
A10: 46207 | B10: Trophy | C10: 50 | D10: 8300 | E10: =C10*D10 -> 415000 | F10: Eniola Marketer | G10: ann-INV178 | I10: Maltina Bottle | J10: =C14 -> 10 | K10: =E14 -> 129200 | L10: =K10/K$13 -> 0.017773449
A11: 46207 | B11: Fayrouz Can | C11: 3 | D11: 13460 | E11: =C11*D11 -> 40380 | F11: Jeff SR | G11: ann-INV179 | I11: Goldberg 60cl | J11: =C15 -> 1 | K11: =E15 -> 9500 | L11: =K11/K$13 -> 0.0013068713
A12: 46207 | B12: Heineken Bottle 60cl | C12: 300 | D12: 12830 | E12: =C12*D12 -> 3849000 | F12: Looking Good | G12: ann-INV177 | I12: Heineken Sleek Can | J12: =C5+C7+C17 -> 11 | K12: =E5+E7+E17 -> 189840 | L12: =K12/K$13 -> 0.026115415
A13: 46207 | B13: Legend Bottle 60cl | C13: 40 | D13: 10915 | E13: =C13*D13 -> 436600 | F13: Looking Good | G13: ann-INV177 | I13: Grand Total | J13: =C18 -> 756 | K13: =SUM(K2:K12) -> 7269270 | L13: =SUM(L2:L12) -> 1
A14: 46207 | B14: Maltina Bottle | C14: 10 | D14: 12920 | E14: =C14*D14 -> 129200 | F14: Looking Good | G14: ann-INV177
A15: 46207 | B15: Goldberg 60cl | C15: 1 | D15: 9500 | E15: =C15*D15 -> 9500 | F15: Remilekun | G15: ann-INV180
A16: 46207 | B16: Maltina Pet 33cl | C16: 5 | D16: 5300 | E16: =C16*D16 -> 26500 | F16: Mr Godswill | G16: ann-INV181
A17: 46207 | B17: Heineken Sleek Can | C17: 1 | D17: 17840 | E17: =C17*D17 -> 17840 | F17: Mr Godswill | G17: ann-INV181
B18: Grand Total | C18: =SUM(C2:C17) -> 756 | D18: =SUM(D2:D17) -> 184250 | E18: =SUM(E2:E17) -> 7269270
I20: Customer | J20: Amount_NGN | K20: % of Total Revenue
I21: Walk in Customer 1 | J21: =E2 -> 27000 | K21: =J21/E$18 -> 0.0037142657
I22: Walk in Customer 2 | J22: =E3 -> 150000 | K22: =J22/E$18 -> 0.020634809
I23: Eniola Marketer | J23: =E10 -> 415000 | K23: =J23/E$18 -> 0.057089639
I24: Rita SR | J24: =SUM(E4:E9) -> 2168250 | K24: =J24/E$18 -> 0.29827617
I25: Jeff SR | J25: =E11 -> 40380 | K25: =J25/E$18 -> 0.0055548907
I26: Looking Good | J26: =SUM(E12:E14) -> 4414800 | K26: =J26/E$18 -> 0.60732371
I27: Remilekun | J27: =E15 -> 9500 | K27: =J27/E$18 -> 0.0013068713
I28: Mr Godswill | J28: =E16+E17 -> 44340 | K28: =J28/E$18 -> 0.0060996496
I29: Total | J29: =SUM(J21:J28) -> 7269270 | K29: 1
I32: Invoice_no | J32: Amount_NGN | K32: Gross Profit
I33: ann-INV173 | J33: 27000 | K33: 0.1
I34: ann-INV174 | J34: 150000 | K34: -0.04
I35: ann-INV175 | J35: 1326000 | K35: -0.04
I36: ann-INV176 | J36: 842250 | K36: -0.02
I37: ann-INV177 | J37: 4939800 | K37: 0
I38: ann-INV178 | J38: 495000 | K38: 0.02
I39: ann-INV179 | J39: 40380 | K39: 0.04
I40: ann-INV180 | J40: 9500 | K40: 0.09
I41: ann-INV181 | J41: 44340 | K41: 0.03
I42: Total | J42: =SUM(J33:J41) -> 7874270

Sheet July 5th Sales Report
A1: July 5th, 2026
A2: No sales recorded - store closed (Sunday).

Sheet July 6th Sales Report
A1: Date | B1: Product | C1: Cases_Sold | D1: Unit_Price_NGN | E1: Amount_NGN | F1: Customer | G1: Invoice No | I1: Product | J1: Quantity | K1: Revenue | L1: % of Total Revenue | N1: Total Revnue | O1: Total Cases Sold | P1: Total transaction
A2: 46209 | B2: Maltina Pet 33cl | C2: 330 | D2: 4950 | E2: =C2*D2 -> 1633500 | F2: AZ Marketer | G2: ann-INV183 | I2: Maltina Pet 33cl | J2: =C2+C15+C23 -> 431 | K2: =E2+E15+E23 -> 2133800 | L2: =K2/K$15 -> 0.31123354 | N2: =K15 -> 6855945 | O2: =J15 -> 931 | P2: =COUNT(J2:J14) -> 13
A3: 46209 | B3: Maltina Pet 50cl | C3: 130 | D3: 7800 | E3: =C3*D3 -> 1014000 | F3: AZ Marketer | G3: ann-INV183 | I3: Maltina Pet 50cl | J3: =C3 -> 130 | K3: =E3 -> 1014000 | L3: =K3/K$15 -> 0.14790084
A4: 46209 | B4: Heineken Bottle 60cl | C4: 60 | D4: 13335 | E4: =C4*D4 -> 800100 | F4: Eniola Marketer | G4: ann-INV184 | I4: Heineken Bottle 60cl | J4: =C4+C11+C17+C25 -> 73 | K4: =E4+E11+E17+E25 -> 973455 | L4: =K4/K$15 -> 0.14198699
A5: 46209 | B5: Medium Stout | C5: 1 | D5: 18300 | E5: =C5*D5 -> 18300 | F5: Mrs Oladejo | G5: ann-INV185 | I5: Medium Stout | J5: =C5 -> 1 | K5: =E5 -> 18300 | L5: =K5/K$15 -> 0.0026692163
A6: 46209 | B6: 33 Export 60cl | C6: 30 | D6: 9200 | E6: =C6*D6 -> 276000 | F6: Eniola Marketer | G6: ann-INV186 | I6: 33 Export 60cl | J6: =C6+C10+C18+C21+C29 -> 81 | K6: =E6+E10+E18+E21+E29 -> 740040 | L6: =K6/K$15 -> 0.10794136
A7: 46209 | B7: Goldberg 60cl | C7: 30 | D7: 9200 | E7: =C7*D7 -> 276000 | F7: Eniola Marketer | G7: ann-INV186 | I7: Goldberg 60cl | J7: =C7+C14+C16+C20+C24+C28+C31 -> 175 | K7: =E7+E14+E16+E20+E24+E28+E31 -> 1593800 | L7: =K7/K$15 -> 0.23246978
A8: 46209 | B8: Trophy | C8: 20 | D8: 8300 | E8: =C8*D8 -> 166000 | F8: Eniola Marketer | G8: ann-INV186 | I8: Trophy | J8: =C8 -> 20 | K8: =E8 -> 166000 | L8: =K8/K$15 -> 0.024212563
A9: 46209 | B9: Turbo King Bottle 60cl | C9: 12 | D9: 9200 | E9: =C9*D9 -> 110400 | F9: Eniola Marketer | G9: ann-INV186 | I9: Turbo King Bottle 60cl | J9: =C9+C26+C30 -> 14 | K9: =E9+E26+E30 -> 128780 | L9: =K9/K$15 -> 0.018783698
A10: 46209 | B10: 33 Export 60cl | C10: 21 | D10: 9200 | E10: =C10*D10 -> 193200 | F10: Ameh Mathew | G10: ann-INV187 | I10: Gulder Bottle | J10: =C12 -> 1 | K10: =E12 -> 11910 | L10: =K10/K$15 -> 0.0017371785
A11: 46209 | B11: Heineken Bottle 60cl | C11: 7 | D11: 13335 | E11: =C11*D11 -> 93345 | F11: Ameh Mathew | G11: ann-INV187 | I11: Star Radler 45cl | J11: =C13 -> 1 | K11: =E13 -> 14575 | L11: =K11/K$15 -> 0.0021258922
A12: 46209 | B12: Gulder Bottle | C12: 1 | D12: 11910 | E12: =C12*D12 -> 11910 | F12: Ameh Mathew | G12: ann-INV187 | I12: Maltina Bottle | J12: =C19 -> 1 | K12: =E19 -> 13550 | L12: =K12/K$15 -> 0.0019763869
A13: 46209 | B13: Star Radler 45cl | C13: 1 | D13: 14575 | E13: =C13*D13 -> 14575 | F13: Ameh Mathew | G13: ann-INV187 | I13: STK 33cl | J13: =C22 -> 2 | K13: =E22 -> 26250 | L13: =K13/K$15 -> 0.0038287938
A14: 46209 | B14: Goldberg 60cl | C14: 4 | D14: 8600 | E14: =C14*D14 -> 34400 | F14: TD Odiolowo | G14: ann-INV188 | I14: Desperados Bottle | J14: =C27 -> 1 | K14: =E27 -> 21485 | L14: =K14/K$15 -> 0.0031337766
A15: 46209 | B15: Maltina Pet 33cl | C15: 100 | D15: 4950 | E15: =C15*D15 -> 495000 | F15: AZ Marketer | G15: ann-INV189 | I15: Grand Total | J15: =SUM(J2:J14) -> 931 | K15: =SUM(K2:K14) -> 6855945 | L15: =K15/K$15 -> 1
A16: 46209 | B16: Goldberg 60cl | C16: 4 | D16: 9200 | E16: =C16*D16 -> 36800 | F16: Jeff SR | G16: ann-INV191
A17: 46209 | B17: Heineken Bottle 60cl | C17: 2 | D17: 13335 | E17: =C17*D17 -> 26670 | F17: Jeff SR | G17: ann-INV191 | I17: Customer | J17: Amount_NGN | K17: % of Total Revenue | L17: Gross Profit
A18: 46209 | B18: 33 Export 60cl | C18: 3 | D18: 9200 | E18: =C18*D18 -> 27600 | F18: Jeff SR | G18: ann-INV191 | I18: AZ Marketer | J18: =E2+E3+E15 -> 3142500 | K18: =J18/J$29 -> 0.45836132 | L18: -0.0295
A19: 46209 | B19: Maltina Bottle | C19: 1 | D19: 13550 | E19: =C19*D19 -> 13550 | F19: Jeff SR | G19: ann-INV191 | I19: Eniola Marketer | J19: =E4+E6+E7+E8+E9 -> 1628500 | K19: =J19/J$29 -> 0.23753108 | L19: 0.0377
A20: 46209 | B20: Goldberg 60cl | C20: 70 | D20: 8990 | E20: =C20*D20 -> 629300 | F20: WURAOLA | G20: ann-INV192 | I20: Mrs Oladejo | J20: =E5 -> 18300 | K20: =J20/J$29 -> 0.0026692163 | L20: 0.0628
A21: 46209 | B21: 33 Export 60cl | C21: 26 | D21: 8990 | E21: =C21*D21 -> 233740 | F21: WURAOLA | G21: ann-INV192 | I21: Ameh Mathew | J21: =E10+E11+E12+E13 -> 313030 | K21: =J21/J$29 -> 0.045658184 | L21: 0.0257
A22: 46209 | B22: STK 33cl | C22: 2 | D22: 13125 | E22: =C22*D22 -> 26250 | F22: Mr Godswill | G22: ann-INV193 | I22: TD Odiolowo | J22: =E14 -> 34400 | K22: =J22/J$29 -> 0.0050175432 | L22: -0.0044
A23: 46209 | B23: Maltina Pet 33cl | C23: 1 | D23: 5300 | E23: =C23*D23 -> 5300 | F23: Mr Godswill | G23: ann-INV193 | I23: Jeff SR | J23: =E16+E17+E18+E19 -> 104620 | K23: =J23/J$29 -> 0.015259749 | L23: 0.0392
A24: 46209 | B24: Goldberg 60cl | C24: 64 | D24: 9200 | E24: =C24*D24 -> 588800 | F24: Tmoney NB | G24: ann-INV190 | I24: WURAOLA | J24: =E20+E21 -> 863040 | K24: =J24/J$29 -> 0.12588199 | L24: 0.0286
A25: 46209 | B25: Heineken Bottle 60cl | C25: 4 | D25: 13335 | E25: =C25*D25 -> 53340 | F25: Tmoney NB | G25: ann-INV190 | I25: Mr Godswill | J25: =E22+E23 -> 31550 | K25: =J25/J$29 -> 0.0046018456 | L25: 0.0498
A26: 46209 | B26: Turbo King Bottle 60cl | C26: 1 | D26: 8880 | E26: =C26*D26 -> 8880 | F26: Tmoney NB | G26: ann-INV190 | I26: Tmoney NB | J26: =E24+E25+E26+E27 -> 672505 | K26: =J26/J$29 -> 0.098090781 | L26: 0.0511
A27: 46209 | B27: Desperados Bottle | C27: 1 | D27: 21485 | E27: =C27*D27 -> 21485 | F27: Tmoney NB | G27: ann-INV190 | I27: Walk in Customer | J27: =E28+E29+E30 -> 28500 | K27: =J27/J$29 -> 0.0041569762 | L27: 0.0824
A28: 46209 | B28: Goldberg 60cl | C28: 1 | D28: 9500 | E28: =C28*D28 -> 9500 | F28: Walk in Customer | G28: ann-INV194 | I28: MRS IK. | J28: =E31 -> 19000 | K28: =J28/J$29 -> 0.0027713174 | L28: 0.0908
A29: 46209 | B29: 33 Export 60cl | C29: 1 | D29: 9500 | E29: =C29*D29 -> 9500 | F29: Walk in Customer | G29: ann-INV194 | I29: Total | J29: =SUM(J18:J28) -> 6855945 | K29: =J29/J$29 -> 1
A30: 46209 | B30: Turbo King Bottle 60cl | C30: 1 | D30: 9500 | E30: =C30*D30 -> 9500 | F30: Walk in Customer | G30: ann-INV194
A31: 46209 | B31: Goldberg 60cl | C31: 2 | D31: 9500 | E31: =C31*D31 -> 19000 | F31: MRS IK. | G31: ann-INV195 | I31: Invoice No | J31: Amount_NGN | K31: Gross Profit
B32: Grand Total | C32: =SUM(C2:C31) -> 931 | D32: =SUM(D2:D31) -> 315445 | E32: =SUM(E2:E31) -> 6855945 | I32: ann-INV183 | J32: 2647500 | K32: -0.03
I33: ann-INV184 | J33: 890100 | K33: 0.04
I34: ann-INV185 | J34: 18300 | K34: 0.06
I35: ann-INV186 | J35: 968400 | K35: 0.04
I36: ann-INV187 | J36: 358030 | K36: 0.03
I37: ann-INV188 | J37: 34400 | K37: 0
I38: ann-INV189 | J38: 495000 | K38: -0.05
I39: ann-INV191 | J39: 119620 | K39: 0.04
I40: ann-INV192 | J40: 863040 | K40: 0.03
...

Sheet July 7th Sales Report
A1: Date | B1: Product | C1: Cases_Sold | D1: Unit_Price_NGN | E1: Amount_NGN | F1: Customer | G1: Invoice No | I1: Product | J1: Quantity | K1: Revenue | L1: % of Total Revenue | N1: Total Revnue | O1: Total Cases Sold | P1: Total transaction
A2: 46210 | B2: Goldberg 60cl | C2: 140 | D2: 8990 | E2: =C2*D2 -> 1258600 | F2: WURAOLA | G2: ann-INV197 | I2: Goldberg 60cl | J2: =C2+C7+C12+C13+C27 -> 403 | K2: =E2+E7+E12+E13+E27 -> 3540800 | L2: =K2/K$16 -> 0.25325048 | N2: =K16 -> 13981415 | O2: =J16 -> 1685 | P2: =COUNT(J2:J15) -> 14
A3: 46210 | B3: 33 Export 60cl | C3: 44 | D3: 8990 | E3: =C3*D3 -> 395560 | F3: WURAOLA | G3: ann-INV197 | I3: 33 Export 60cl | J3: =C3+C11+C15+C26+C32 -> 224 | K3: =E3+E11+E15+E26+E32 -> 2032510 | L3: =K3/K$16 -> 0.14537227
A4: 46210 | B4: Maltina Pet 33cl | C4: 120 | D4: 5100 | E4: =C4*D4 -> 612000 | F4: DESOLA STORE | G4: ann-INV196 | I4: Maltina Pet 33cl | J4: =C4+C5+C17+C22+C38 -> 603 | K4: =E4+E5+E17+E22+E38 -> 3011800 | L4: =K4/K$16 -> 0.21541453
A5: 46210 | B5: Maltina Pet 33cl | C5: 250 | D5: 4950 | E5: =C5*D5 -> 1237500 | F5: Demola SR | G5: ann-INV198 | I5: Heineken Sleek Can | J5: =C6+C20 -> 11 | K5: =E6+E20 -> 189100 | L5: =K5/K$16 -> 0.013525097
A6: 46210 | B6: Heineken Sleek Can | C6: 10 | D6: 17200 | E6: =C6*D6 -> 172000 | F6: Rita SR | G6: ann-INV199 | I6: Heineken Bottle 60cl | J6: =C8+C10+C24+C34 -> 262 | K6: =E8+E10+E24+E34 -> 3394545 | L6: =K6/K$16 -> 0.2427898
A7: 46210 | B7: Goldberg 60cl | C7: 25 | D7: 9200 | E7: =C7*D7 -> 230000 | F7: Eniola Marketer | G7: ann-INV200 | I7: Turbo King Bottle 60cl | J7: =C9+C16+C25+C28+C36 -> 67 | K7: =E9+E16+E25+E28+E36 -> 594160 | L7: =K7/K$16 -> 0.042496414
A8: 46210 | B8: Heineken Bottle 60cl | C8: 17 | D8: 13335 | E8: =C8*D8 -> 226695 | F8: Eniola Marketer | G8: ann-INV200 | I8: Star Radler 45cl | J8: =C14 -> 2 | K8: =E14 -> 29150 | L8: =K8/K$16 -> 0.0020849106
A9: 46210 | B9: Turbo King Bottle 60cl | C9: 10 | D9: 9200 | E9: =C9*D9 -> 92000 | F9: Eniola Marketer | G9: ann-INV200 | I9: Maltina Pet 50cl | J9: =C18+C23+C37 -> 55 | K9: =E18+E23+E37 -> 441100 | L9: =K9/K$16 -> 0.031549024
A10: 46210 | B10: Heineken Bottle 60cl | C10: 210 | D10: 12930 | E10: =C10*D10 -> 2715300 | F10: Rukky bee | G10: ann-INV201 | I10: Gulder Bottle | J10: =C19+C31 -> 23 | K10: =E19+E31 -> 264030 | L10: =K10/K$16 -> 0.018884355
A11: 46210 | B11: 33 Export 60cl | C11: 140 | D11: 9090 | E11: =C11*D11 -> 1272600 | F11: Rukky bee | G11: ann-INV201 | I11: Goldberg Can 50cl | J11: =C21 -> 1 | K11: =E21 -> 16145 | L11: =K11/K$16 -> 0.0011547472
A12: 46210 | B12: Goldberg 60cl | C12: 11 | D12: 8600 | E12: =C12*D12 -> 94600 | F12: TD Odiolowo | G12: ann-INV202 | I12: Desperados Bottle | J12: =C29 -> 6 | K12: =E29 -> 123240 | L12: =K12/K$16 -> 0.0088145585
A13: 46210 | B13: Goldberg 60cl | C13: 27 | D13: 8800 | E13: =C13*D13 -> 237600 | F13: Ameh Mathew | G13: ann-INV203 | I13: Legend Bottle 60cl | J13: =C30 -> 15 | K13: =E30 -> 172200 | L13: =K13/K$16 -> 0.01231635
A14: 46210 | B14: Star Radler 45cl | C14: 2 | D14: 14575 | E14: =C14*D14 -> 29150 | F14: Ameh Mathew | G14: ann-INV203 | I14: Maltina Bottle | J14: =C33 -> 10 | K14: =E33 -> 130200 | L14: =K14/K$16 -> 0.0093123622
A15: 46210 | B15: 33 Export 60cl | C15: 5 | D15: 9200 | E15: =C15*D15 -> 46000 | F15: Ameh Mathew | G15: ann-INV203 | I15: Goldberg Black 45cl | J15: =C35 -> 3 | K15: =E35 -> 42435 | L15: =K15/K$16 -> 0.0030351005
A16: 46210 | B16: Turbo King Bottle 60cl | C16: 5 | D16: 8880 | E16: =C16*D16 -> 44400 | F16: Ameh Mathew | G16: ann-INV203 | I16: Grand Total | J16: =SUM(J2:J15) -> 1685 | K16: =SUM(K2:K15) -> 13981415 | L16: =K16/K$16 -> 1
A17: 46210 | B17: Maltina Pet 33cl | C17: 30 | D17: 4900 | E17: =C17*D17 -> 147000 | F17: Ameh Mathew | G17: ann-INV203
A18: 46210 | B18: Maltina Pet 50cl | C18: 15 | D18: 8020 | E18: =C18*D18 -> 120300 | F18: Ameh Mathew | G18: ann-INV203 | I18: Customer | J18: Amount_NGN | K18: % of Total Revenue | L18: Gross Profit
A19: 46210 | B19: Gulder Bottle | C19: 3 | D19: 11910 | E19: =C19*D19 -> 35730 | F19: Ameh Mathew | G19: ann-INV203 | I19: WURAOLA | J19: =E2+E3 -> 1654160 | K19: =J19/J$32 -> 0.11831134 | L19: 0.0256
A20: 46210 | B20: Heineken Sleek Can | C20: 1 | D20: 17100 | E20: =C20*D20 -> 17100 | F20: Ameh Mathew | G20: ann-INV203 | I20: DESOLA STORE | J20: =E4 -> 612000 | K20: =J20/J$32 -> 0.043772394 | L20: -0.0196
A21: 46210 | B21: Goldberg Can 50cl | C21: 1 | D21: 16145 | E21: =C21*D21 -> 16145 | F21: Ameh Mathew | G21: ann-INV203 | I21: Demola SR | J21: =E5 -> 1237500 | K21: =J21/J$32 -> 0.088510355 | L21: -0.0505
A22: 46210 | B22: Maltina Pet 33cl | C22: 202 | D22: 5000 | E22: =C22*D22 -> 1010000 | F22: Mr Lekan Ojifini | G22: ann-INV204 | I22: Rita SR | J22: =E6 -> 172000 | K22: =J22/J$32 -> 0.012302045 | L22: 0.0058
A23: 46210 | B23: Maltina Pet 50cl | C23: 20 | D23: 8020 | E23: =C23*D23 -> 160400 | F23: Mr Lekan Ojifini | G23: ann-INV204 | I23: Eniola Marketer | J23: =E7+E8+E9 -> 548695 | K23: =J23/J$32 -> 0.039244597 | L23: 0.0491
A24: 46210 | B24: Heineken Bottle 60cl | C24: 30 | D24: 12930 | E24: =C24*D24 -> 387900 | F24: Tmoney NB | G24: ann-INV205 | I24: Rukky bee | J24: =E10+E11 -> 3987900 | K24: =J24/J$32 -> 0.28522864 | L24: 0.0116
A25: 46210 | B25: Turbo King Bottle 60cl | C25: 10 | D25: 8800 | E25: =C25*D25 -> 88000 | F25: Tmoney NB | G25: ann-INV205 | I25: TD Odiolowo | J25: =E12 -> 94600 | K25: =J25/J$32 -> 0.0067661249 | L25: -0.0037
A26: 46210 | B26: 33 Export 60cl | C26: 20 | D26: 9100 | E26: =C26*D26 -> 182000 | F26: Tmoney NB | G26: ann-INV205 | I26: Ameh Mathew | J26: =E13+E14+E15+E16+E17+E18+E19+E20+E21+E36 -> 711185 | K26: =J26/J$32 -> 0.050866454 | L26: 0.0088
A27: 46210 | B27: Goldberg 60cl | C27: 200 | D27: 8600 | E27: =C27*D27 -> 1720000 | F27: Emmycee | G27: ann-INV206 | I27: Mr Lekan Ojifini | J27: =E22+E23 -> 1170400 | K27: =J27/J$32 -> 0.083711127 | L27: -0.0288
A28: 46210 | B28: Turbo King Bottle 60cl | C28: 40 | D28: 8800 | E28: =C28*D28 -> 352000 | F28: Emmycee | G28: ann-INV206 | I28: Tmoney NB | J28: =E24+E25+E26 -> 657900 | K28: =J28/J$32 -> 0.047055323 | L28: 0.0139
A29: 46210 | B29: Desperados Bottle | C29: 6 | D29: 20540 | E29: =C29*D29 -> 123240 | F29: Emmycee | G29: ann-INV206 | I29: Emmycee | J29: =E27+E28+E29+E30+E31+E32+E33+E34+E35 -> 2969375 | K29: =J29/J$32 -> 0.21238015 | L29: 0.0492
A30: 46210 | B30: Legend Bottle 60cl | C30: 15 | D30: 11480 | E30: =C30*D30 -> 172200 | F30: Emmycee | G30: ann-INV206 | I30: Jeff SR | J30: =E37 -> 160400 | K30: =J30/J$32 -> 0.011472372 | L30: 0.0418
A31: 46210 | B31: Gulder Bottle | C31: 20 | D31: 11415 | E31: =C31*D31 -> 228300 | F31: Emmycee | G31: ann-INV206 | I31: Walk in Customer | J31: =E38 -> 5300 | K31: =J31/J$32 -> 0.00037907465 | L31: 0.0189
A32: 46210 | B32: 33 Export 60cl | C32: 15 | D32: 9090 | E32: =C32*D32 -> 136350 | F32: Emmycee | G32: ann-INV206 | I32: Total | J32: =SUM(J19:J31) -> 13981415 | K32: =J32/J$32 -> 1
A33: 46210 | B33: Maltina Bottle | C33: 10 | D33: 13020 | E33: =C33*D33 -> 130200 | F33: Emmycee | G33: ann-INV206
A34: 46210 | B34: Heineken Bottle 60cl | C34: 5 | D34: 12930 | E34: =C34*D34 -> 64650 | F34: Emmycee | G34: ann-INV206 | I34: Invoice No | J34: Amount_NGN | K34: Gross Profit
A35: 46210 | B35: Goldberg Black 45cl | C35: 3 | D35: 14145 | E35: =C35*D35 -> 42435 | F35: Emmycee | G35: ann-INV206 | I35: ann-INV197 | J35: 1930160 | K35: 0.03
A36: 46210 | B36: Turbo King Bottle 60cl | C36: 2 | D36: 8880 | E36: =C36*D36 -> 17760 | F36: Ameh Mathew | G36: ann-INV207 | I36: ann-INV196 | J36: 612000 | K36: -0.02
A37: 46210 | B37: Maltina Pet 50cl | C37: 20 | D37: 8020 | E37: =C37*D37 -> 160400 | F37: Jeff SR | G37: ann-INV208 | I37: ann-INV198 | J37: 1237500 | K37: -0.05
A38: 46210 | B38: Maltina Pet 33cl | C38: 1 | D38: 5300 | E38: =C38*D38 -> 5300 | F38: Walk in Customer | G38: ann-INV209 | I38: ann-INV199 | J38: 172000 | K38: 0.01
B39: Grand Total | C39: =SUM(C2:C38) -> 1685 | D39: =SUM(D2:D38) -> 383185 | E39: =SUM(E2:E38) -> 13981415 | I39: ann-INV200 | J39: 626695 | K39: 0.05
I40: ann-INV201 | J40: 4512900 | K40: 0.01
...

Sheet July 8th Sales Report
A1: Date | B1: Product | C1: Cases_Sold | D1: Unit_Price_NGN | E1: Amount_NGN | F1: Customer | G1: Invoice No | I1: Product | J1: Quantity | K1: Revenue | L1: % of Total Revenue | N1: Total Revnue | O1: Total Cases Sold | P1: Total transaction
A2: 46211 | B2: Heineken Bottle 60cl | C2: 5 | D2: 13335 | E2: =C2*D2 -> 66675 | F2: Amandla | G2: ann-INV210 | I2: Heineken Bottle 60cl | J2: =C2+C12+C16+C24+C37 -> 137 | K2: =E2+E12+E16+E24+E37 -> 1774245 | L2: =K2/K$22 -> 0.22243068 | N2: =K22 -> 7976620 | O2: =J22 -> 844 | P2: =COUNT(J2:J21) -> 20
A3: 46211 | B3: Desperados Bottle | C3: 5 | D3: 21485 | E3: =C3*D3 -> 107425 | F3: Amandla | G3: ann-INV210 | I3: Desperados Bottle | J3: =C3 -> 5 | K3: =E3 -> 107425 | L3: =K3/K$22 -> 0.013467484
A4: 46211 | B4: Gulder Bottle | C4: 5 | D4: 11910 | E4: =C4*D4 -> 59550 | F4: Amandla | G4: ann-INV210 | I4: Gulder Bottle | J4: =C4+C14+C25+C38 -> 19 | K4: =E4+E14+E25+E38 -> 226290 | L4: =K4/K$22 -> 0.028369159
A5: 46211 | B5: Maltina Bottle | C5: 5 | D5: 13550 | E5: =C5*D5 -> 67750 | F5: Amandla | G5: ann-INV210 | I5: Maltina Bottle | J5: =C5+C27 -> 10 | K5: =E5+E27 -> 135500 | L5: =K5/K$22 -> 0.016987145
A6: 46211 | B6: Fayrouz Bottle | C6: 2 | D6: 10315 | E6: =C6*D6 -> 20630 | F6: Ameh Mathew | G6: ann-INV212 | I6: Fayrouz Bottle | J6: =C6+C31 -> 4 | K6: =E6+E31 -> 41260 | L6: =K6/K$22 -> 0.005172617
A7: 46211 | B7: Tiger Bottle | C7: 1 | D7: 15525 | E7: =C7*D7 -> 15525 | F7: Ameh Mathew | G7: ann-INV212 | I7: Tiger Bottle | J7: =C7+C41 -> 7 | K7: =E7+E41 -> 108675 | L7: =K7/K$22 -> 0.013624192
A8: 46211 | B8: Amstel Bottle | C8: 1 | D8: 14450 | E8: =C8*D8 -> 14450 | F8: Ameh Mathew | G8: ann-INV212 | I8: Amstel Bottle | J8: =C8+C26+C34 -> 5 | K8: =E8+E26+E34 -> 72250 | L8: =K8/K$22 -> 0.0090577212
A9: 46211 | B9: Legend Bottle 60cl | C9: 2 | D9: 11480 | E9: =C9*D9 -> 22960 | F9: Ameh Mathew | G9: ann-INV212 | I9: Legend Bottle 60cl | J9: =C9 -> 2 | K9: =E9 -> 22960 | L9: =K9/K$22 -> 0.0028784122
A10: 46211 | B10: Heineken Sleek Can | C10: 20 | D10: 17100 | E10: =C10*D10 -> 342000 | F10: Ameh Mathew | G10: ann-INV211 | I10: Heineken Sleek Can | J10: =C10+C29 -> 25 | K10: =E10+E29 -> 431225 | L10: =K10/K$22 -> 0.054061119
A11: 46211 | B11: Goldberg Can 50cl | C11: 25 | D11: 16145 | E11: =C11*D11 -> 403625 | F11: Ameh Mathew | G11: ann-INV211 | I11: Goldberg Can 50cl | J11: =C11 -> 25 | K11: =E11 -> 403625 | L11: =K11/K$22 -> 0.050601006
A12: 46211 | B12: Heineken Bottle 60cl | C12: 10 | D12: 12930 | E12: =C12*D12 -> 129300 | F12: Delayers | G12: ann-INV213 | I12: 33 Export 60cl | J12: =C13 -> 4 | K12: =E13 -> 36800 | L12: =K12/K$22 -> 0.0046134829
A13: 46211 | B13: 33 Export 60cl | C13: 4 | D13: 9200 | E13: =C13*D13 -> 36800 | F13: Solomon | G13: ann-INV214 | I13: Turbo King Bottle 60cl | J13: =C15+C22+C36 -> 55 | K13: =E15+E22+E36 -> 490000 | L13: =K13/K$22 -> 0.061429528
A14: 46211 | B14: Gulder Bottle | C14: 2 | D14: 11910 | E14: =C14*D14 -> 23820 | F14: Solomon | G14: ann-INV214 | I14: Maltina Pet 50cl | J14: =C17+C20 -> 20 | K14: =E17+E20 -> 160400 | L14: =K14/K$22 -> 0.020108768
A15: 46211 | B15: Turbo King Bottle 60cl | C15: 4 | D15: 9200 | E15: =C15*D15 -> 36800 | F15: Solomon | G15: ann-INV214 | I15: Goldberg 60cl | J15: =C18+C21+C30+C35 -> 310 | K15: =E18+E21+E30+E35 -> 2672300 | L15: =K15/K$22 -> 0.33501659
A16: 46211 | B16: Heineken Bottle 60cl | C16: 2 | D16: 13335 | E16: =C16*D16 -> 26670 | F16: Solomon | G16: ann-INV214 | I16: Maltina Pet 33cl | J16: =C19+C28+C43 -> 190 | K16: =E19+E28+E43 -> 950000 | L16: =K16/K$22 -> 0.11909806
A17: 46211 | B17: Maltina Pet 50cl | C17: 10 | D17: 8020 | E17: =C17*D17 -> 80200 | F17: Solomon | G17: ann-INV214 | I17: STK 33cl | J17: =C23 -> 1 | K17: =E23 -> 13125 | L17: =K17/K$22 -> 0.0016454338
A18: 46211 | B18: Goldberg 60cl | C18: 1 | D18: 9500 | E18: =C18*D18 -> 9500 | F18: Remilekun | G18: ann-INV215 | I18: Star Bottle 60cl | J18: =C32 -> 3 | K18: =E32 -> 34800 | L18: =K18/K$22 -> 0.0043627501
A19: 46211 | B19: Maltina Pet 33cl | C19: 30 | D19: 5000 | E19: =C19*D19 -> 150000 | F19: Ahmed SR | G19: ann-INV216 | I19: Goldberg Black 45cl | J19: =C33+C40 -> 7 | K19: =E33+E40 -> 99015 | L19: =K19/K$22 -> 0.012413152
A20: 46211 | B20: Maltina Pet 50cl | C20: 10 | D20: 8020 | E20: =C20*D20 -> 80200 | F20: Ahmed SR | G20: ann-INV216 | I20: Williams Bottle 60cl | J20: =C39 -> 10 | K20: =E39 -> 93450 | L20: =K20/K$22 -> 0.011715489
A21: 46211 | B21: Goldberg 60cl | C21: 4 | D21: 9200 | E21: =C21*D21 -> 36800 | F21: Walk in Customer | G21: ann-INV218 | I21: ACE BITTERS | J21: =C42 -> 5 | K21: =E42 -> 103275 | L21: =K21/K$22 -> 0.012947213
A22: 46211 | B22: Turbo King Bottle 60cl | C22: 1 | D22: 9200 | E22: =C22*D22 -> 9200 | F22: Walk in Customer | G22: ann-INV218 | I22: Grand Total | J22: =SUM(J2:J21) -> 844 | K22: =SUM(K2:K21) -> 7976620 | L22: =K22/K$22 -> 1
A23: 46211 | B23: STK 33cl | C23: 1 | D23: 13125 | E23: =C23*D23 -> 13125 | F23: Mr Godswill | G23: ann-INV219
A24: 46211 | B24: Heineken Bottle 60cl | C24: 60 | D24: 12930 | E24: =C24*D24 -> 775800 | F24: Tmoney NB | G24: ann-INV220 | I24: Customer | J24: Amount_NGN | K24: % of Total Revenue | L24: Gross Profit
A25: 46211 | B25: Gulder Bottle | C25: 2 | D25: 11910 | E25: =C25*D25 -> 23820 | F25: Tmoney NB | G25: ann-INV220 | I25: Amandla | J25: =E2+E3+E4+E5 -> 301400 | K25: =J25/J$39 -> 0.037785428 | L25: 0.1058
A26: 46211 | B26: Amstel Bottle | C26: 3 | D26: 14450 | E26: =C26*D26 -> 43350 | F26: Tmoney NB | G26: ann-INV220 | I26: Ameh Mathew | J26: =E6+E7+E8+E9+E10+E11 -> 819190 | K26: =J26/J$39 -> 0.10269889 | L26: 0.0331
A27: 46211 | B27: Maltina Bottle | C27: 5 | D27: 13550 | E27: =C27*D27 -> 67750 | F27: Tmoney NB | G27: ann-INV220 | I27: Delayers | J27: =E12 -> 129300 | K27: =J27/J$39 -> 0.016209873 | L27: 0.137
A28: 46211 | B28: Maltina Pet 33cl | C28: 150 | D28: 5000 | E28: =C28*D28 -> 750000 | F28: Eniola Marketer | G28: ann-INV222 | I28: Solomon | J28: =E13+E14+E15+E16+E17 -> 204290 | K28: =J28/J$39 -> 0.025611098 | L28: 0.0706
A29: 46211 | B29: Heineken Sleek Can | C29: 5 | D29: 17845 | E29: =C29*D29 -> 89225 | F29: Eniola Marketer | G29: ann-INV222 | I29: Remilekun | J29: =E18 -> 9500 | K29: =J29/J$39 -> 0.0011909806 | L29: 0.0908
A30: 46211 | B30: Goldberg 60cl | C30: 5 | D30: 9200 | E30: =C30*D30 -> 46000 | F30: Ola SR | G30: ann-INV221 | I30: Ahmed SR | J30: =E19+E20+E43 -> 280200 | K30: =J30/J$39 -> 0.035127661 | L30: -0.0166
A31: 46211 | B31: Fayrouz Bottle | C31: 2 | D31: 10315 | E31: =C31*D31 -> 20630 | F31: Ola SR | G31: ann-INV221 | I31: Walk in Customer | J31: =E21+E22 -> 46000 | K31: =J31/J$39 -> 0.0057668536 | L31: 0.0805
A32: 46211 | B32: Star Bottle 60cl | C32: 3 | D32: 11600 | E32: =C32*D32 -> 34800 | F32: Ola SR | G32: ann-INV221 | I32: Mr Godswill | J32: =E23 -> 13125 | K32: =J32/J$39 -> 0.0016454338 | L32: 0.0817
A33: 46211 | B33: Goldberg Black 45cl | C33: 2 | D33: 14145 | E33: =C33*D33 -> 28290 | F33: Ola SR | G33: ann-INV221 | I33: Tmoney NB | J33: =E24+E25+E26+E27 -> 910720 | K33: =J33/J$39 -> 0.11417367 | L33: 0.1259
A34: 46211 | B34: Amstel Bottle | C34: 1 | D34: 14450 | E34: =C34*D34 -> 14450 | F34: Ola SR | G34: ann-INV221 | I34: Eniola Marketer | J34: =E28+E29 -> 839225 | K34: =J34/J$39 -> 0.1052106 | L34: -0.0313
A35: 46211 | B35: Goldberg 60cl | C35: 300 | D35: 8600 | E35: =C35*D35 -> 2580000 | F35: Mama Oyin Mowe | G35: ann-INV223 | I35: Ola SR | J35: =E30+E31+E32+E33+E34 -> 144170 | K35: =J35/J$39 -> 0.018074071 | L35: 0.0646
A36: 46211 | B36: Turbo King Bottle 60cl | C36: 50 | D36: 8880 | E36: =C36*D36 -> 444000 | F36: Mama Oyin Mowe | G36: ann-INV223 | I36: Mama Oyin Mowe | J36: =E35+E36 -> 3024000 | K36: =J36/J$39 -> 0.37910794 | L36: 0.0487
A37: 46211 | B37: Heineken Bottle 60cl | C37: 60 | D37: 12930 | E37: =C37*D37 -> 775800 | F37: Mr Musefiu | G37: ann-INV224 | I37: Mr Musefiu | J37: =E37 -> 775800 | K37: =J37/J$39 -> 0.09725924 | L37: 0.0142
A38: 46211 | B38: Gulder Bottle | C38: 10 | D38: 11910 | E38: =C38*D38 -> 119100 | F38: Mr Lekan Ojifini | G38: ann-INV227 | I38: Mr Lekan Ojifini | J38: =E38+E39+E40+E41+E42 -> 479700 | K38: =J38/J$39 -> 0.060138254 | L38: 0.0609
A39: 46211 | B39: Williams Bottle 60cl | C39: 10 | D39: 9345 | E39: =C39*D39 -> 93450 | F39: Mr Lekan Ojifini | G39: ann-INV227 | I39: Total | J39: =SUM(J25:J38) -> 7976620 | K39: =J39/J$39 -> 1
A40: 46211 | B40: Goldberg Black 45cl | C40: 5 | D40: 14145 | E40: =C40*D40 -> 70725 | F40: Mr Lekan Ojifini | G40: ann-INV227
...

Sheet July 9th Sales Report
A1: Date | B1: Product | C1: Cases_Sold | D1: Unit_Price_NGN | E1: Amount_NGN | F1: Customer | G1: Invoice No | I1: Product | J1: Quantity | K1: Revenue | L1: % of Total Revenue | N1: Total Revnue | O1: Total Cases Sold | P1: Total transaction
A2: 46212 | B2: Heineken Bottle 60cl | C2: 60 | D2: 12930 | E2: =C2*D2 -> 775800 | F2: Delayers | G2: ann-INV229 | I2: Heineken Bottle 60cl | J2: =C2+C36+C42+C46 -> 69 | K2: =E2+E36+E42+E46 -> 895815 | L2: =K2/K$24 -> 0.28770806 | N2: =K24 -> 3113625 | O2: =J24 -> 236 | P2: =COUNT(J2:J23) -> 22
A3: 46212 | B3: Desperados Can | C3: 10 | D3: 21695 | E3: =C3*D3 -> 216950 | F3: Ameh Mathew | G3: ann-INV230 | I3: Desperados Can | J3: =C3 -> 10 | K3: =E3 -> 216950 | L3: =K3/K$24 -> 0.069677627
A4: 46212 | B4: Amstel Bottle | C4: 2 | D4: 14450 | E4: =C4*D4 -> 28900 | F4: Rita SR | G4: ann-INV231 | I4: Amstel Bottle | J4: =C4+C41 -> 3 | K4: =E4+E41 -> 43350 | L4: =K4/K$24 -> 0.013922679
A5: 46212 | B5: Fayrouz Bottle | C5: 2 | D5: 10315 | E5: =C5*D5 -> 20630 | F5: Rita SR | G5: ann-INV231 | I5: Fayrouz Bottle | J5: =C5 -> 2 | K5: =E5 -> 20630 | L5: =K5/K$24 -> 0.0066257176
A6: 46212 | B6: Fayrouz Can | C6: 3 | D6: 13350 | E6: =C6*D6 -> 40050 | F6: Rita SR | G6: ann-INV231 | I6: Fayrouz Can | J6: =C6+C38 -> 4 | K6: =E6+E38 -> 53510 | L6: =K6/K$24 -> 0.017185756
A7: 46212 | B7: ACE BITTERS | C7: 3 | D7: 20655 | E7: =C7*D7 -> 61965 | F7: Rita SR | G7: ann-INV231 | I7: ACE BITTERS | J7: =C7 -> 3 | K7: =E7 -> 61965 | L7: =K7/K$24 -> 0.019901241
A8: 46212 | B8: Gulder Bottle | C8: 10 | D8: 11910 | E8: =C8*D8 -> 119100 | F8: Rita SR | G8: ann-INV231 | I8: Gulder Bottle | J8: =C8+C15+C23+C29+C35+C43 -> 24 | K8: =E8+E15+E23+E29+E35+E43 -> 285840 | L8: =K8/K$24 -> 0.091802963
A9: 46212 | B9: Tiger Bottle | C9: 4 | D9: 15525 | E9: =C9*D9 -> 62100 | F9: Rita SR | G9: ann-INV231 | I9: Tiger Bottle | J9: =C9+C17+C25+C30+C34 -> 11 | K9: =E9+E17+E25+E30+E34 -> 170775 | L9: =K9/K$24 -> 0.054847645
A10: 46212 | B10: 33 Export 60cl | C10: 2 | D10: 9200 | E10: =C10*D10 -> 18400 | F10: Rita SR | G10: ann-INV231 | I10: 33 Export 60cl | J10: =C10+C26+C32+C45 -> 15 | K10: =E10+E26+E32+E45 -> 138000 | L10: =K10/K$24 -> 0.04432133
A11: 46212 | B11: Maltina Pet 50cl | C11: 30 | D11: 8020 | E11: =C11*D11 -> 240600 | F11: Rita SR | G11: ann-INV231 | I11: Maltina Pet 50cl | J11: =C11 -> 30 | K11: =E11 -> 240600 | L11: =K11/K$24 -> 0.077273275
A12: 46212 | B12: Heineken Can 50cl | C12: 20 | D12: 23770 | E12: =C12*D12 -> 475400 | F12: Rita SR | G12: ann-INV231 | I12: Heineken Can 50cl | J12: =C12 -> 20 | K12: =E12 -> 475400 | L12: =K12/K$24 -> 0.15268377
A13: 46212 | B13: Williams Bottle 60cl | C13: 2 | D13: 9345 | E13: =C13*D13 -> 18690 | F13: Rita SR | G13: ann-INV231 | I13: Williams Bottle 60cl | J13: =C13+C16+C24+C28 -> 9 | K13: =E13+E16+E24+E28 -> 84105 | L13: =K13/K$24 -> 0.027011923
A14: 46212 | B14: Legend Can 44cl | C14: 5 | D14: 21170 | E14: =C14*D14 -> 105850 | F14: Rita SR | G14: ann-INV231 | I14: Legend Can 44cl | J14: =C14 -> 5 | K14: =E14 -> 105850 | L14: =K14/K$24 -> 0.033995745
A15: 46212 | B15: Gulder Bottle | C15: 3 | D15: 11910 | E15: =C15*D15 -> 35730 | F15: Ahmed SR | G15: ann-INV232 | I15: Turbo King Bottle 60cl | J15: =C18+C37+C44 -> 6 | K15: =E18+E37+E44 -> 53280 | L15: =K15/K$24 -> 0.017111887
A16: 46212 | B16: Williams Bottle 60cl | C16: 3 | D16: 9345 | E16: =C16*D16 -> 28035 | F16: Ahmed SR | G16: ann-INV232 | I16: Trophy | J16: =C19+C50 -> 5 | K16: =E19+E50 -> 43000 | L16: =K16/K$24 -> 0.013810269
A17: 46212 | B17: Tiger Bottle | C17: 2 | D17: 15525 | E17: =C17*D17 -> 31050 | F17: Ahmed SR | G17: ann-INV232 | I17: Goldberg 60cl | J17: =C20+C27+C31+C47+C49 -> 11 | K17: =E20+E27+E31+E47+E49 -> 98700 | L17: =K17/K$24 -> 0.031699386
A18: 46212 | B18: Turbo King Bottle 60cl | C18: 3 | D18: 8880 | E18: =C18*D18 -> 26640 | F18: Ahmed SR | G18: ann-INV232 | I18: Smirnoff Ice. | J18: =C21 -> 1 | K18: =E21 -> 17000 | L18: =K18/K$24 -> 0.0054598739
A19: 46212 | B19: Trophy | C19: 4 | D19: 8500 | E19: =C19*D19 -> 34000 | F19: tomaco | G19: ann-INV233 | I19: Medium Stout | J19: =C22 -> 1 | K19: =E22 -> 18300 | L19: =K19/K$24 -> 0.0058773937
A20: 46212 | B20: Goldberg 60cl | C20: 2 | D20: 9200 | E20: =C20*D20 -> 18400 | F20: tomaco | G20: ann-INV233 | I20: Desperados Bottle | J20: =C33 -> 2 | K20: =E33 -> 42800 | L20: =K20/K$24 -> 0.013746036
A21: 46212 | B21: Smirnoff Ice. | C21: 1 | D21: 17000 | E21: =C21*D21 -> 17000 | F21: tomaco | G21: ann-INV233 | I21: Star Bottle 60cl | J21: =C39 -> 1 | K21: =E39 -> 11415 | L21: =K21/K$24 -> 0.0036661448
A22: 46212 | B22: Medium Stout | C22: 1 | D22: 18300 | E22: =C22*D22 -> 18300 | F22: tomaco | G22: ann-INV233 | I22: Maltina Bottle | J22: =C40 -> 2 | K22: =E40 -> 26040 | L22: =K22/K$24 -> 0.0083632422
A23: 46212 | B23: Gulder Bottle | C23: 4 | D23: 11910 | E23: =C23*D23 -> 47640 | F23: Solomon | G23: ann-INV234 | I23: Maltina Pet 33cl | J23: =C48+C51 -> 2 | K23: =E48+E51 -> 10300 | L23: =K23/K$24 -> 0.0033080413
A24: 46212 | B24: Williams Bottle 60cl | C24: 2 | D24: 9345 | E24: =C24*D24 -> 18690 | F24: Solomon | G24: ann-INV234 | I24: Grand Total | J24: =SUM(J2:J23) -> 236 | K24: =SUM(K2:K23) -> 3113625 | L24: =K24/K$24 -> 1
A25: 46212 | B25: Tiger Bottle | C25: 1 | D25: 15525 | E25: =C25*D25 -> 15525 | F25: Solomon | G25: ann-INV234
A26: 46212 | B26: 33 Export 60cl | C26: 1 | D26: 9200 | E26: =C26*D26 -> 9200 | F26: Walk in Customer | G26: ann-INV235 | I26: Customer | J26: Amount_NGN | K26: % of Total Revenue | L26: Gross Profit
A27: 46212 | B27: Goldberg 60cl | C27: 1 | D27: 9200 | E27: =C27*D27 -> 9200 | F27: Walk in Customer | G27: ann-INV235 | I27: Delayers | J27: =E2 -> 775800 | K27: =J27/J$36 -> 0.24916295 | L27: 0.137
